Workbook

Sheet Lojas
A1: ID | B1: Nome | C1: Estado | D1: Cidade | E1: Porte | F1: Grupo
A2: 1 | B2: ABC Multimarcas | C2: SP | D2: Campinas | E2: Grande | F2: ABC Auto
A3: 2 | B3: MGP Multimarcas | C3: RJ | D3: Rio de Janeiro | E3: Médio | F3: MGP Motor
A4: 3 | B4: MGP Multimarcas | C4: SP | D4: Sumaré | E4: Médio | F4: MGP Motor
A5: 4 | B5: TTY Revenda Usados | C5: MG | D5: Belo Horizonte | E5: Pequeno | F5: TTY Revenda Auto
A6: 5 | B6: BBV Multimarcas | C6: SP | D6: Araraquara | E6: Grande | F6: BBV Auto
A7: 6 | B7: ABC Multimarcas | C7: SP | D7: Hortolândia | E7: Médio | F7: ABC Auto
A8: 7 | B8: WWU Multimarcas | C8: AM | D8: Manaus | E8: Médio | F8: WWU Auto Motor
A9: 8 | B9: HHF Auto | C9: PB | D9: João Pessoa | E9: Pequeno | F9: HHF Car

Sheet Vendas
A1: ID | B1: Data | C1: Hora | D1: Carro | E1: Cor | F1: Ano | G1: Modelo | H1: KM | I1: Marca | J1: Valor | K1: Loja | L1: Estado | M1: Cidade | N1: Comissão
A2: 1 | B2: 43344 | C2: 0.53125 | D2: Gol | E2: Branco | F2: 2018 | G2: 2019 | H2: 0 | I2: VW | J2: 45000 | K2: 1 | L2: =VLOOKUP(K2,Lojas!A$2:F$9,3) -> SP | M2: =VLOOKUP(K2,Lojas!A$2:F$9,4) -> Campinas | N2: 0.05
A3: 2 | B3: 43344 | C3: 0.6875 | D3: Fox | E3: Preto | F3: 2015 | G3: 2015 | H3: 12000 | I3: VW | J3: 48000 | K3: 2 | L3: =VLOOKUP(K3,Lojas!A$2:F$9,3) -> RJ | M3: =VLOOKUP(K3,Lojas!A$2:F$9,4) -> Rio de Janeiro | N3: 0.02
A4: 3 | B4: 43344 | C4: 0.34166667 | D4: Prisma | E4: Branco | F4: 2010 | G4: 2011 | H4: 35000 | I4: GM | J4: 30000 | K4: 3 | L4: =VLOOKUP(K4,Lojas!A$2:F$9,3) -> SP | M4: =VLOOKUP(K4,Lojas!A$2:F$9,4) -> Sumaré | N4: 0.03
A5: 4 | B5: 43345 | C5: 0.32638889 | D5: Gol | E5: Vermelho | F5: 2010 | G5: 2011 | H5: 90000 | I5: VW | J5: 20000 | K5: 4 | L5: =VLOOKUP(K5,Lojas!A$2:F$9,3) -> MG | M5: =VLOOKUP(K5,Lojas!A$2:F$9,4) -> Belo Horizonte | N5: 0.05
A6: 5 | B6: 43345 | C6: 0.38541667 | D6: Ranger | E6: Branco | F6: 2008 | G6: 2009 | H6: 120000 | I6: Ford | J6: 58000 | K6: 5 | L6: =VLOOKUP(K6,Lojas!A$2:F$9,3) -> SP | M6: =VLOOKUP(K6,Lojas!A$2:F$9,4) -> Araraquara | N6: 0.02
A7: 6 | B7: 43346 | C7: 0.375 | D7: Punto | E7: Amarelo | F7: 2010 | G7: 2010 | H7: 80000 | I7: Fiat | J7: 40000 | K7: 1 | L7: =VLOOKUP(K7,Lojas!A$2:F$9,3) -> SP | M7: =VLOOKUP(K7,Lojas!A$2:F$9,4) -> Campinas | N7: 0.05
A8: 7 | B8: 43347 | C8: 0.43402778 | D8: Toro | E8: Preto | F8: 2018 | G8: 2019 | H8: 0 | I8: Fiat | J8: 90000 | K8: 6 | L8: =VLOOKUP(K8,Lojas!A$2:F$9,3) -> SP | M8: =VLOOKUP(K8,Lojas!A$2:F$9,4) -> Hortolândia | N8: 0.08
A9: 8 | B9: 43347 | C9: 0.55138889 | D9: KA | E9: Branco | F9: 2018 | G9: 2018 | H9: 0 | I9: Ford | J9: 40000 | K9: 2 | L9: =VLOOKUP(K9,Lojas!A$2:F$9,3) -> RJ | M9: =VLOOKUP(K9,Lojas!A$2:F$9,4) -> Rio de Janeiro | N9: 0.01
A10: 9 | B10: 43347 | C10: 0.46805556 | D10: Fox | E10: Prata | F10: 2015 | G10: 2016 | H10: 45000 | I10: VW | J10: 35000 | K10: 7 | L10: =VLOOKUP(K10,Lojas!A$2:F$9,3) -> AM | M10: =VLOOKUP(K10,Lojas!A$2:F$9,4) -> Manaus | N10: 0.07
A11: 10 | B11: 43348 | C11: 0.65277778 | D11: Celta | E11: Prata | F11: 2008 | G11: 2008 | H11: 160000 | I11: GM | J11: 16000 | K11: 8 | L11: =VLOOKUP(K11,Lojas!A$2:F$9,3) -> PB | M11: =VLOOKUP(K11,Lojas!A$2:F$9,4) -> João Pessoa | N11: 0.03
A12: 11 | B12: 43348 | C12: 0.34722222 | D12: Fox | E12: Prata | F12: 2018 | G12: 2018 | H12: 0 | I12: VW | J12: 47000 | K12: 1 | L12: =VLOOKUP(K12,Lojas!A$2:F$9,3) -> SP | M12: =VLOOKUP(K12,Lojas!A$2:F$9,4) -> Campinas | N12: 0.02
A13: 12 | B13: 43348 | C13: 0.35416667 | D13: Mobi | E13: Branco | F13: 2017 | G13: 2018 | H13: 35000 | I13: Fiat | J13: 38000 | K13: 1 | L13: =VLOOKUP(K13,Lojas!A$2:F$9,3) -> SP | M13: =VLOOKUP(K13,Lojas!A$2:F$9,4) -> Campinas | N13: 0.01
... A51: 50 | B51: 43501 | C51: 0.34375 | D51: Strada | E51: Branco | F51: 2015 | G51: 2015 | H51: 30000 | I51: Fiat | J51: 40000 | K51: 8 | L51: =VLOOKUP(K51,Lojas!A$2:F$9,3) -> PB | M51: =VLOOKUP(K51,Lojas!A$2:F$9,4) -> João Pessoa | N51: 0.05

Sheet Tab_Vendas
A1: KM | B1: (Tudo)
A3: Rótulos de Linha | B3: Soma de Valor
A4: AM | B4: 409000
A5: Fox | B5: 35000
A6: Ranger | B6: 125000
A7: Toro | B7: 90000
A8: UP | B8: 45000
A9: S10 | B9: 55000
A10: Ecosport | B10: 59000
A11: MG | B11: 214000
A12: Cruze | B12: 80000
A13: Gol | B13: 20000
A14: KA | B14: 44000
A15: Focus | B15: 70000
... A48: Total Geral | B48: 2437000

Sheet Tab_Lojas+Vendas
A1: Data_Ano | B1: All
A2: Data_Mês | B2: All
A3: Data_Dia | B3: All
A5: Nome | B5: Cidade | C5: Carro | D5: Total Vendido | E5: Quantidade | F5: Faturamento | G5: Comissão | H5: Lucro | I5: % Lucro
A6: ABC Multimarcas | B6: Campinas | C6: Fox | D6: 47000 | E6: 1 | F6: 940 | G6: 0.02 | H6: 752 | I6: 0.0080143235
C7: Fusion | D7: 120000 | E7: 1 | F7: 9600 | G7: 0.08 | H7: 7680 | I7: 0.08184841
C8: Gol | D8: 153000 | E8: 4 | F8: 5760 | G8: 0.15 | H8: 4608 | I8: 0.049109046
C9: Mobi | D9: 38000 | E9: 1 | F9: 380 | G9: 0.01 | H9: 304 | I9: 0.0032398329
C10: Punto | D10: 40000 | E10: 1 | F10: 2000 | G10: 0.05 | H10: 1600 | I10: 0.017051752
C11: Ranger | D11: 80000 | E11: 1 | F11: 5600 | G11: 0.07 | H11: 4480 | I11: 0.047744906
C12: Uno | D12: 18000 | E12: 1 | F12: 540 | G12: 0.03 | H12: 432 | I12: 0.0046039731
C13: UP | D13: 40000 | E13: 1 | F13: 2800 | G13: 0.07 | H13: 2240 | I13: 0.023872453
B14: Campinas Total | D14: 536000 | E14: 11 | F14: 27620 | G14: 0.48 | H14: 22096 | I14: 0.2354847
B16: Hortolândia | C16: Cobalt | D16: 50000 | E16: 1 | F16: 3500 | G16: 0.07 | H16: 2800 | I16: 0.029840566
C17: KA | D17: 35000 | E17: 1 | F17: 700 | G17: 0.02 | H17: 560 | I17: 0.0059681132
C18: Spin | D18: 65000 | E18: 1 | F18: 2600 | G18: 0.04 | H18: 2080 | I18: 0.022167278
C19: Toro | D19: 160000 | E19: 2 | F19: 12100 | G19: 0.15 | H19: 9680 | I19: 0.1031631
B20: Hortolândia Total | D20: 310000 | E20: 5 | F20: 18900 | G20: 0.28 | H20: 15120 | I20: 0.16113906
A22: ABC Multimarcas Total | D22: 846000 | E22: 16 | F22: 46520 | G22: 0.76 | H22: 37216 | I22: 0.39662375
A24: MGP Multimarcas | B24: Rio de Janeiro | C24: Fox | D24: 89000 | E24: 2 | F24: 4650 | G24: 0.11 | H24: 3720 | I24: 0.039645324
C25: Jetta | D25: 45000 | E25: 1 | F25: 1350 | G25: 0.03 | H25: 1080 | I25: 0.011509933
C26: KA | D26: 40000 | E26: 1 | F26: 400 | G26: 0.01 | H26: 320 | I26: 0.0034103504
C27: Onix | D27: 33000 | E27: 1 | F27: 1650 | G27: 0.05 | H27: 1320 | I27: 0.014067695
B28: Rio de Janeiro Total | D28: 207000 | E28: 5 | F28: 8050 | G28: 0.2 | H28: 6440 | I28: 0.068633302
B30: Sumaré | C30: Focus | D30: 35000 | E30: 1 | F30: 1050 | G30: 0.03 | H30: 840 | I30: 0.0089521698
C31: Fox | D31: 48000 | E31: 1 | F31: 1920 | G31: 0.04 | H31: 1536 | I31: 0.016369682
C32: Onix | D32: 39000 | E32: 1 | F32: 1560 | G32: 0.04 | H32: 1248 | I32: 0.013300367
C33: Palio | D33: 28000 | E33: 1 | F33: 1680 | G33: 0.06 | H33: 1344 | I33: 0.014323472
C34: Prisma | D34: 30000 | E34: 1 | F34: 900 | G34: 0.03 | H34: 720 | I34: 0.0076732884
C35: Strada | D35: 38000 | E35: 1 | F35: 2280 | G35: 0.06 | H35: 1824 | I35: 0.019438997
C36: Uno | D36: 22000 | E36: 1 | F36: 440 | G36: 0.02 | H36: 352 | I36: 0.0037513855
B37: Sumaré Total | D37: 240000 | E37: 7 | F37: 9830 | G37: 0.28 | H37: 7864 | I37: 0.083809361
A39: MGP Multimarcas Total | D39: 447000 | E39: 12 | F39: 17880 | G39: 0.48 | H39: 14304 | I39: 0.15244266
A41: HHF Auto | B41: João Pessoa | C41: Amarok | D41: 75000 | E41: 1 | F41: 6000 | G41: 0.08 | H41: 4800 | I41: 0.051155256
C42: Celta | D42: 16000 | E42: 1 | F42: 480 | G42: 0.03 | H42: 384 | I42: 0.0040924205
C43: Cruze | D43: 85000 | E43: 1 | F43: 3400 | G43: 0.04 | H43: 2720 | I43: 0.028987979
C44: Fiesta | D44: 86000 | E44: 2 | F44: 2680 | G44: 0.06 | H44: 2144 | I44: 0.022849348
C45: Mobi | D45: 30000 | E45: 1 | F45: 1200 | G45: 0.04 | H45: 960 | I45: 0.010231051
C46: Strada | D46: 40000 | E46: 1 | F46: 2000 | G46: 0.05 | H46: 1600 | I46: 0.017051752
C47: UP | D47: 29000 | E47: 1 | F47: 290 | G47: 0.01 | H47: 232 | I47: 0.002472504
...
